============================= test session starts ==============================
platform linux -- Python 3.10.12, pytest-8.3.3, pluggy-1.5.0
rootdir: /home/wilkinson/Documents/TCC/TG
collected 4 items

QuixBugs/python_testcases/test_kheapsort.py F...                         [100%]

=================================== FAILURES ===================================
____________________ test_kheapsort[input_data0-expected0] _____________________

input_data = [[1, 2, 3, 4, 5], 0], expected = [1, 2, 3, 4, 5]

    @pytest.mark.parametrize("input_data,expected", testdata)
    def test_kheapsort(input_data, expected):
>       assert list(kheapsort(*input_data)) == expected

QuixBugs/python_testcases/test_kheapsort.py:15: 
_ _ _ _ _ _ _ _ _ _ _ _ _ _ _ _ _ _ _ _ _ _ _ _ _ _ _ _ _ _ _ _ _ _ _ _ _ _ _ _ 

arr = [1, 2, 3, 4, 5], k = 0

    def kheapsort(arr, k):
        if k <= 0:
>           raise ValueError("k must be greater than 0")
E           ValueError: k must be greater than 0

QuixBugs/python_programs/kheapsort.py:5: ValueError
=========================== short test summary info ============================
FAILED QuixBugs/python_testcases/test_kheapsort.py::test_kheapsort[input_data0-expected0]
========================= 1 failed, 3 passed in 0.04s ==========================
Different AST

prover a correção mas introduz novo bug
