============================= test session starts ==============================
platform linux -- Python 3.10.12, pytest-8.3.3, pluggy-1.5.0
rootdir: /home/wilkinson/Documents/TCC/TG
collected 5 items

QuixBugs/python_testcases/test_next_palindrome.py ....F                  [100%]

=================================== FAILURES ===================================
_________________ test_next_palindrome[input_data4-expected4] __________________

input_data = [[0, 0, 0]], expected = [1, 0, 0, 1]

    @pytest.mark.parametrize("input_data,expected", testdata)
    def test_next_palindrome(input_data, expected):
>       assert next_palindrome(*input_data) == expected
E       assert [1, 1, 1] == [1, 0, 0, 1]
E         
E         At index 1 diff: 1 != 0
E         Right contains one more item: 1
E         Use -v to get more diff

QuixBugs/python_testcases/test_next_palindrome.py:15: AssertionError
=========================== short test summary info ============================
FAILED QuixBugs/python_testcases/test_next_palindrome.py::test_next_palindrome[input_data4-expected4]
========================= 1 failed, 4 passed in 0.03s ==========================
Different AST

tenta corrigir outra coisa
