============================= test session starts ==============================
platform linux -- Python 3.10.12, pytest-8.3.3, pluggy-1.5.0
rootdir: /home/wilkinson/Documents/TCC/TG
collected 12 items

QuixBugs/python_testcases/test_lis.py ....F.....F.                       [100%]

=================================== FAILURES ===================================
___________________________ test_lis[input_data4-4] ____________________________

input_data = [[5, 1, 3, 4, 7]], expected = 4

    @pytest.mark.parametrize("input_data,expected", testdata)
    def test_lis(input_data, expected):
>       assert lis(*input_data) == expected
E       assert 2 == 4
E        +  where 2 = lis(*[[5, 1, 3, 4, 7]])

QuixBugs/python_testcases/test_lis.py:15: AssertionError
___________________________ test_lis[input_data10-3] ___________________________

input_data = [[7, 10, 9, 2, 3, 8, ...]], expected = 3

    @pytest.mark.parametrize("input_data,expected", testdata)
    def test_lis(input_data, expected):
>       assert lis(*input_data) == expected
E       assert 2 == 3
E        +  where 2 = lis(*[[7, 10, 9, 2, 3, 8, ...]])

QuixBugs/python_testcases/test_lis.py:15: AssertionError
=========================== short test summary info ============================
FAILED QuixBugs/python_testcases/test_lis.py::test_lis[input_data4-4] - asser...
FAILED QuixBugs/python_testcases/test_lis.py::test_lis[input_data10-3] - asse...
========================= 2 failed, 10 passed in 0.04s =========================
Different AST

tenta resolver qualquer outra coisa
