============================= test session starts ==============================
platform linux -- Python 3.10.12, pytest-8.3.3, pluggy-1.5.0
rootdir: /home/wilkinson/Documents/TCC/TG
collected 5 items

QuixBugs/python_testcases/test_next_palindrome.py FF.F.                  [100%]

=================================== FAILURES ===================================
_________________ test_next_palindrome[input_data0-expected0] __________________

input_data = [[1, 4, 9, 4, 1]], expected = [1, 5, 0, 5, 1]

    @pytest.mark.parametrize("input_data,expected", testdata)
    def test_next_palindrome(input_data, expected):
>       assert next_palindrome(*input_data) == expected
E       assert [1, 4, 9, 9, 4] == [1, 5, 0, 5, 1]
E
E         At index 1 diff: 4 != 5
E         Use -v to get more diff

QuixBugs/python_testcases/test_next_palindrome.py:15: AssertionError
_________________ test_next_palindrome[input_data1-expected1] __________________

input_data = [[1, 3, 1]], expected = [1, 4, 1]

    @pytest.mark.parametrize("input_data,expected", testdata)
    def test_next_palindrome(input_data, expected):
>       assert next_palindrome(*input_data) == expected
E       assert [1, 3, 3] == [1, 4, 1]
E         
E         At index 1 diff: 3 != 4
E         Use -v to get more diff

QuixBugs/python_testcases/test_next_palindrome.py:15: AssertionError
_________________ test_next_palindrome[input_data3-expected3] __________________

input_data = [[4, 7, 2, 5, 2, 7, ...]], expected = [4, 7, 2, 6, 2, 7, ...]

    @pytest.mark.parametrize("input_data,expected", testdata)
    def test_next_palindrome(input_data, expected):
>       assert next_palindrome(*input_data) == expected
E       assert [4, 7, 2, 5, 5, 2, ...] == [4, 7, 2, 6, 2, 7, ...]
E         
E         At index 3 diff: 5 != 6
E         Use -v to get more diff

QuixBugs/python_testcases/test_next_palindrome.py:15: AssertionError
=========================== short test summary info ============================
FAILED QuixBugs/python_testcases/test_next_palindrome.py::test_next_palindrome[input_data0-expected0]
FAILED QuixBugs/python_testcases/test_next_palindrome.py::test_next_palindrome[input_data1-expected1]
FAILED QuixBugs/python_testcases/test_next_palindrome.py::test_next_palindrome[input_data3-expected3]
========================= 3 failed, 2 passed in 0.04s ==========================
Different AST

tenta resolver outra coisa

