============================= test session starts ==============================
platform linux -- Python 3.10.12, pytest-8.3.3, pluggy-1.5.0
rootdir: /home/wilkinson/Documents/TCC/TG
collected 7 items

QuixBugs/python_testcases/test_find_first_in_sorted.py F......           [100%]

=================================== FAILURES ===================================
___________________ test_find_first_in_sorted[input_data0-2] ___________________

input_data = [[3, 4, 5, 5, 5, 5, ...], 5], expected = 2

    @pytest.mark.parametrize("input_data,expected", testdata)
    def test_find_first_in_sorted(input_data, expected):
>       assert find_first_in_sorted(*input_data) == expected
E       assert -1 == 2
E        +  where -1 = find_first_in_sorted(*[[3, 4, 5, 5, 5, 5, ...], 5])

QuixBugs/python_testcases/test_find_first_in_sorted.py:15: AssertionError
=========================== short test summary info ============================
FAILED QuixBugs/python_testcases/test_find_first_in_sorted.py::test_find_first_in_sorted[input_data0-2]
========================= 1 failed, 6 passed in 0.04s ==========================
Different AST

tenta resolver outra coisa
