============================= test session starts ==============================
platform linux -- Python 3.10.12, pytest-8.3.3, pluggy-1.5.0
rootdir: /home/wilkinson/Documents/TCC/TG
collected 7 items

QuixBugs/python_testcases/test_kth.py .FF....                            [100%]

=================================== FAILURES ===================================
___________________________ test_kth[input_data1-7] ____________________________

input_data = [[3, 6, 7, 1, 6, 3, ...], 5], expected = 7

    @pytest.mark.parametrize("input_data,expected", testdata)
    def test_kth(input_data, expected):
>       assert kth(*input_data) == expected
E       assert 9 == 7
E        +  where 9 = kth(*[[3, 6, 7, 1, 6, 3, ...], 5])

QuixBugs/python_testcases/test_kth.py:15: AssertionError
___________________________ test_kth[input_data2-3] ____________________________

input_data = [[3, 6, 7, 1, 6, 3, ...], 2], expected = 3

    @pytest.mark.parametrize("input_data,expected", testdata)
    def test_kth(input_data, expected):
>       assert kth(*input_data) == expected
E       assert 6 == 3
E        +  where 6 = kth(*[[3, 6, 7, 1, 6, 3, ...], 2])

QuixBugs/python_testcases/test_kth.py:15: AssertionError
=========================== short test summary info ============================
FAILED QuixBugs/python_testcases/test_kth.py::test_kth[input_data1-7] - asser...
FAILED QuixBugs/python_testcases/test_kth.py::test_kth[input_data2-3] - asser...
========================= 2 failed, 5 passed in 0.04s ==========================
Different AST

tenta resolver outra coisa
